Workbook

Sheet 产品表 Products
A1: 类别 Category | B1: 类别（中文） | C1: 型号 Model | D1: 产品类型 Type | E1: 中文名称 | F1: 招标常见叫法 Tender terms | G1: 行程 Stroke | H1: 单位 Unit | I1: 行程换算 (° / mm) | J1: 出力 Force (N) | K1: 出力类型 | L1: 刚度 Stiffness (N/µm) | M1: 谐振频率 Resonance (Hz) | N1: 电容 Capacitance (µF) | O1: 尺寸 Dimensions | P1: 其他参数 Other specs | Q1: 选项 Options | R1: 状态 Status | S1: 应用 / 说明 (EN) | T1: 产品链接 Product page | U1: 数据表 Datasheet | V1: 符合速查条件 | W1: _序号 | X1: _url
A2: Amplified Piezo Actuators (APA) | B2: 放大型压电促动器 | C2: APA30uXS | D2: Amplified Piezo Actuator | E2: 放大型压电促动器 | F2: 压电促动器、压电陶瓷驱动器、压电作动器、压电致动器、压电陶瓷执行器、放大式压电促动器、柔性铰链放大压电 | G2: 34 | H2: µm | I2: =IF(H2="mrad",ROUND(G2*180/PI()/1000,2)&"°",IF(H2="µm",G2/1000&" mm","")) -> 0.034 mm | J2: 3.7 | K2: 阻挡力 | L2: 0.11 | M2: 4778 | N2: 0.04 | Q2: 无磁外壳，真空兼容 | R2: 标准品 | S2: Applications: Earing implants – Actuation in Micro Aerial Vehicle – Energy harvester for pacemaker – Micro electro optical systems | T2: 打开 | U2: PDF | V2: =IF(AND(OR('选型速查 Spec Match'!$C$4="全部 All",B2='选型速查 Spec Match'!$C$4),OR('选型速查 Spec Match'!$C$5="",AND(H2='选型速查 Spec Match'!$C$6,N(G2)>='选型速查 Spec Match'!$C$5)),OR('选型速查 Spec Match'!$C$7="",N(J2)>='选型速查 Spec Match'!$C$7),OR('选型速查 Spec Match'!$C$8="",N(M2)>='选型速查 Spec Match'!$C$8)),"✓","") -> ✓ | W2: =IF(V2="✓",COUNTIF($V$2:V2,"✓"),"") -> 1 | X2: https://cedrat-technologies.com/produit/apa30uxs/
A3: Amplified Piezo Actuators (APA) | B3: 放大型压电促动器 | C3: APA35XS | D3: Amplified Piezo Actuator | E3: 放大型压电促动器 | F3: 压电促动器、压电陶瓷驱动器、压电作动器、压电致动器、压电陶瓷执行器、放大式压电促动器、柔性铰链放大压电 | G3: 52 | H3: µm | I3: =IF(H3="mrad",ROUND(G3*180/PI()/1000,2)&"°",IF(H3="µm",G3/1000&" mm","")) -> 0.052 mm | J3: 27 | K3: 阻挡力 | L3: 0.52 | M3: 3880 | N3: 0.3 | Q3: 应变片闭环，无磁外壳，真空兼容 | R3: 标准品 | S3: Applications: Micro optical mechanisms – Micro controllers dynamic valves – Space qualified micro tips tilts – Miniature brakes | T3: 打开 | U3: PDF | V3: =IF(AND(OR('选型速查 Spec Match'!$C$4="全部 All",B3='选型速查 Spec Match'!$C$4),OR('选型速查 Spec Match'!$C$5="",AND(H3='选型速查 Spec Match'!$C$6,N(G3)>='选型速查 Spec Match'!$C$5)),OR('选型速查 Spec Match'!$C$7="",N(J3)>='选型速查 Spec Match'!$C$7),OR('选型速查 Spec Match'!$C$8="",N(M3)>='选型速查 Spec Match'!$C$8)),"✓","") -> ✓ | W3: =IF(V3="✓",COUNTIF($V$2:V3,"✓"),"") -> 2 | X3: https://cedrat-technologies.com/produit/apa35xs/
A4: Amplified Piezo Actuators (APA) | B4: 放大型压电促动器 | C4: APA40SM | D4: Amplified Piezo Actuator | E4: 放大型压电促动器 | F4: 压电促动器、压电陶瓷驱动器、压电作动器、压电致动器、压电陶瓷执行器、放大式压电促动器、柔性铰链放大压电 | G4: 54 | H4: µm | I4: =IF(H4="mrad",ROUND(G4*180/PI()/1000,2)&"°",IF(H4="µm",G4/1000&" mm","")) -> 0.054 mm | J4: 260 | K4: 阻挡力 | L4: 4.9 | M4: 4130 | N4: 1.1 | Q4: 应变片闭环，真空兼容 | R4: 标准品 | S4: Applications: Shock energy harvester in wireless switches – Material stress cycling – Injectors | T4: 打开 | U4: PDF | V4: =IF(AND(OR('选型速查 Spec Match'!$C$4="全部 All",B4='选型速查 Spec Match'!$C$4),OR('选型速查 Spec Match'!$C$5="",AND(H4='选型速查 Spec Match'!$C$6,N(G4)>='选型速查 Spec Match'!$C$5)),OR('选型速查 Spec Match'!$C$7="",N(J4)>='选型速查 Spec Match'!$C$7),OR('选型速查 Spec Match'!$C$8="",N(M4)>='选型速查 Spec Match'!$C$8)),"✓","") -> ✓ | W4: =IF(V4="✓",COUNTIF($V$2:V4,"✓"),"") -> 3 | X4: https://cedrat-technologies.com/produit/apa40sm/
A5: Amplified Piezo Actuators (APA) | B5: 放大型压电促动器 | C5: APA60SL | D5: Amplified Piezo Actuator | E5: 放大型压电促动器 | F5: 压电促动器、压电陶瓷驱动器、压电作动器、压电致动器、压电陶瓷执行器、放大式压电促动器、柔性铰链放大压电 | G5: 57 | H5: µm | I5: =IF(H5="mrad",ROUND(G5*180/PI()/1000,2)&"°",IF(H5="µm",G5/1000&" mm","")) -> 0.057 mm | J5: 390 | K5: 阻挡力 | L5: 6.8 | M5: 3120 | N5: 6.2 | Q5: 应变片闭环，真空兼容 | R5: 标准品 | S5: Applications: Active clamping | T5: 打开 | U5: PDF | V5: =IF(AND(OR('选型速查 Spec Match'!$C$4="全部 All",B5='选型速查 Spec Match'!$C$4),OR('选型速查 Spec Match'!$C$5="",AND(H5='选型速查 Spec Match'!$C$6,N(G5)>='选型速查 Spec Match'!$C$5)),OR('选型速查 Spec Match'!$C$7="",N(J5)>='选型速查 Spec Match'!$C$7),OR('选型速查 Spec Match'!$C$8="",N(M5)>='选型速查 Spec Match'!$C$8)),"✓","") -> ✓ | W5: =IF(V5="✓",COUNTIF($V$2:V5,"✓"),"") -> 4 | X5: https://cedrat-technologies.com/produit/apa60sl/
A6: Amplified Piezo Actuators (APA) | B6: 放大型压电促动器 | C6: APA60ML | D6: Amplified Piezo Actuator | E6: 放大型压电促动器 | F6: 压电促动器、压电陶瓷驱动器、压电作动器、压电致动器、压电陶瓷执行器、放大式压电促动器、柔性铰链放大压电 | G6: 65 | H6: µm | I6: =IF(H6="mrad",ROUND(G6*180/PI()/1000,2)&"°",IF(H6="µm",G6/1000&" mm","")) -> 0.065 mm | J6: 3300 | K6: 阻挡力 | L6: 51 | M6: 2555 | N6: 13 | Q6: 应变片闭环，真空兼容 | R6: 标准品 | S6: Applications: Shaker – Force generator – Heavy load positionner – Dynamic Actuator | T6: 打开 | U6: PDF | V6: =IF(AND(OR('选型速查 Spec Match'!$C$4="全部 All",B6='选型速查 Spec Match'!$C$4),OR('选型速查 Spec Match'!$C$5="",AND(H6='选型速查 Spec Match'!$C$6,N(G6)>='选型速查 Spec Match'!$C$5)),OR('选型速查 Spec Match'!$C$7="",N(J6)>='选型速查 Spec Match'!$C$7),OR('选型速查 Spec Match'!$C$8="",N(M6)>='选型速查 Spec Match'!$C$8)),"✓","") -> ✓ | W6: =IF(V6="✓",COUNTIF($V$2:V6,"✓"),"") -> 5 | X6: https://cedrat-technologies.com/produit/apa60ml/
A7: Amplified Piezo Actuators (APA) | B7: 放大型压电促动器 | C7: APA50XS | D7: Amplified Piezo Actuator | E7: 放大型压电促动器 | F7: 压电促动器、压电陶瓷驱动器、压电作动器、压电致动器、压电陶瓷执行器、放大式压电促动器、柔性铰链放大压电 | G7: 66 | H7: µm | I7: =IF(H7="mrad",ROUND(G7*180/PI()/1000,2)&"°",IF(H7="µm",G7/1000&" mm","")) -> 0.066 mm | J7: 16 | K7: 阻挡力 | L7: 0.24 | M7: 2730 | N7: 0.3 | Q7: 无磁外壳，真空兼容 | R7: 标准品 | S7: Applications: Micro optical mechanisms – Micro controllers dynamic valves – Space qualified micro tips tilts – Miniature brakes | T7: 打开 | U7: PDF | V7: =IF(AND(OR('选型速查 Spec Match'!$C$4="全部 All",B7='选型速查 Spec Match'!$C$4),OR('选型速查 Spec Match'!$C$5="",AND(H7='选型速查 Spec Match'!$C$6,N(G7)>='选型速查 Spec Match'!$C$5)),OR('选型速查 Spec Match'!$C$7="",N(J7)>='选型速查 Spec Match'!$C$7),OR('选型速查 Spec Match'!$C$8="",N(M7)>='选型速查 Spec Match'!$C$8)),"✓","") -> ✓ | W7: =IF(V7="✓",COUNTIF($V$2:V7,"✓"),"") -> 6 | X7: https://cedrat-technologies.com/produit/apa50xs/
A8: Amplified Piezo Actuators (APA) | B8: 放大型压电促动器 | C8: APA60S | D8: Amplified Piezo Actuator | E8: 放大型压电促动器 | F8: 压电促动器、压电陶瓷驱动器、压电作动器、压电致动器、压电陶瓷执行器、放大式压电促动器、柔性铰链放大压电 | G8: 75 | H8: µm | I8: =IF(H8="mrad",ROUND(G8*180/PI()/1000,2)&"°",IF(H8="µm",G8/1000&" mm","")) -> 0.075 mm | J8: 130 | K8: 阻挡力 | L8: 1.7 | M8: 2860 | N8: 1.1 | Q8: 应变片闭环，无磁外壳，真空兼容 | R8: 标准品 | S8: Applications: Shaking powder for X-ray diffraction – Optical stabilization for embedded cameras – Space qualified optical stages – Nano indentation | T8: 打开 | U8: PDF | V8: =IF(AND(OR('选型速查 Spec Match'!$C$4="全部 All",B8='选型速查 Spec Match'!$C$4),OR('选型速查 Spec Match'!$C$5="",AND(H8='选型速查 Spec Match'!$C$6,N(G8)>='选型速查 Spec Match'!$C$5)),OR('选型速查 Spec Match'!$C$7="",N(J8)>='选型速查 Spec Match'!$C$7),OR('选型速查 Spec Match'!$C$8="",N(M8)>='选型速查 Spec Match'!$C$8)),"✓","") -> ✓ | W8: =IF(V8="✓",COUNTIF($V$2:V8,"✓"),"") -> 7 | X8: https://cedrat-technologies.com/produit/apa60s/
A9: Amplified Piezo Actuators (APA) | B9: 放大型压电促动器 | C9: APA60SM | D9: Amplified Piezo Actuator | E9: 放大型压电促动器 | F9: 压电促动器、压电陶瓷驱动器、压电作动器、压电致动器、压电陶瓷执行器、放大式压电促动器、柔性铰链放大压电 | G9: 77 | H9: µm | I9: =IF(H9="mrad",ROUND(G9*180/PI()/1000,2)&"°",IF(H9="µm",G9/1000&" mm","")) -> 0.077 mm | J9: 140 | K9: 阻挡力 | L9: 1.8 | M9: 2802 | N9: 1.1 | Q9: 应变片闭环，无磁外壳，真空兼容 | R9: 标准品 | S9: Applications: Fast X-ray vacuum compatible shutters – dynamic valves – laser cavity tuning – miniature active flaps for aero vehicles | T9: 打开 | U9: PDF | V9: =IF(AND(OR('选型速查 Spec Match'!$C$4="全部 All",B9='选型速查 Spec Match'!$C$4),OR('选型速查 Spec Match'!$C$5="",AND(H9='选型速查 Spec Match'!$C$6,N(G9)>='选型速查 Spec Match'!$C$5)),OR('选型速查 Spec Match'!$C$7="",N(J9)>='选型速查 Spec Match'!$C$7),OR('选型速查 Spec Match'!$C$8="",N(M9)>='选型速查 Spec Match'!$C$8)),"✓","") -> ✓ | W9: =IF(V9="✓",COUNTIF($V$2:V9,"✓"),"") -> 8 | X9: https://cedrat-technologies.com/produit/apa60sm/
A10: Amplified Piezo Actuators (APA) | B10: 放大型压电促动器 | C10: APA95ML | D10: Amplified Piezo Actuator | E10: 放大型压电促动器 | F10: 压电促动器、压电陶瓷驱动器、压电作动器、压电致动器、压电陶瓷执行器、放大式压电促动器、柔性铰链放大压电 | G10: 99 | H10: µm | I10: =IF(H10="mrad",ROUND(G10*180/PI()/1000,2)&"°",IF(H10="µm",G10/1000&" mm","")) -> 0.099 mm | J10: 2100 | K10: 阻挡力 | L10: 21 | M10: 2090 | N10: 13 | Q10: 应变片闭环，真空兼容 | R10: 标准品 | S10: Applications: Active control of vibration on medical robots – High frequency shakers – Fretting fatigue testing – Space qualified positionner | T10: 打开 | U10: PDF | V10: =IF(AND(OR('选型速查 Spec Match'!$C$4="全部 All",B10='选型速查 Spec Match'!$C$4),OR('选型速查 Spec Match'!$C$5="",AND(H10='选型速查 Spec Match'!$C$6,N(G10)>='选型速查 Spec Match'!$C$5)),OR('选型速查 Spec Match'!$C$7="",N(J10)>='选型速查 Spec Match'!$C$7),OR('选型速查 Spec Match'!$C$8="",N(M10)>='选型速查 Spec Match'!$C$8)),"✓","") -> ✓ | W10: =IF(V10="✓",COUNTIF($V$2:V10,"✓"),"") -> 9 | X10: https://cedrat-technologies.com/produit/apa95ml/
A11: Amplified Piezo Actuators (APA) | B11: 放大型压电促动器 | C11: APA100MML | D11: Amplified Piezo Actuator | E11: 放大型压电促动器 | F11: 压电促动器、压电陶瓷驱动器、压电作动器、压电致动器、压电陶瓷执行器、放大式压电促动器、柔性铰链放大压电 | G11: 100 | H11: µm | I11: =IF(H11="mrad",ROUND(G11*180/PI()/1000,2)&"°",IF(H11="µm",G11/1000&" mm","")) -> 0.1 mm | J11: 830 | K11: 阻挡力 | L11: 8.3 | M11: 1730 | N11: 6.3 | Q11: 应变片闭环，真空兼容 | R11: 标准品 | S11: Applications: Active stabilisation of a watt balance – High frequency shakers – Elasto MRI – Long range cavity modulation in interferometers | T11: 打开 | U11: PDF | V11: =IF(AND(OR('选型速查 Spec Match'!$C$4="全部 All",B11='选型速查 Spec Match'!$C$4),OR('选型速查 Spec Match'!$C$5="",AND(H11='选型速查 Spec Match'!$C$6,N(G11)>='选型速查 Spec Match'!$C$5)),OR('选型速查 Spec Match'!$C$7="",N(J11)>='选型速查 Spec Match'!$C$7),OR('选型速查 Spec Match'!$C$8="",N(M11)>='选型速查 Spec Match'!$C$8)),"✓","") -> ✓ | W11: =IF(V11="✓",COUNTIF($V$2:V11,"✓"),"") -> 10 | X11: https://cedrat-technologies.com/produit/apa100mml/
A12: Amplified Piezo Actuators (APA) | B12: 放大型压电促动器 | C12: APA120ML | D12: Amplified Piezo Actuator | E12: 放大型压电促动器 | F12: 压电促动器、压电陶瓷驱动器、压电作动器、压电致动器、压电陶瓷执行器、放大式压电促动器、柔性铰链放大压电 | G12: 120 | H12: µm | I12: =IF(H12="mrad",ROUND(G12*180/PI()/1000,2)&"°",IF(H12="µm",G12/1000&" mm","")) -> 0.12 mm | J12: 1500 | K12: 阻挡力 | L12: 12 | M12: 1880 | N12: 13 | Q12: 应变片闭环，真空兼容 | R12: 标准品 | S12: Applications: Active control of vibration on medical robots – High frequency shakers – Fretting fatigue testing – Space qualified positionner | T12: 打开 | U12: PDF | V12: =IF(AND(OR('选型速查 Spec Match'!$C$4="全部 All",B12='选型速查 Spec Match'!$C$4),OR('选型速查 Spec Match'!$C$5="",AND(H12='选型速查 Spec Match'!$C$6,N(G12)>='选型速查 Spec Match'!$C$5)),OR('选型速查 Spec Match'!$C$7="",N(J12)>='选型速查 Spec Match'!$C$7),OR('选型速查 Spec Match'!$C$8="",N(M12)>='选型速查 Spec Match'!$C$8)),"✓","") -> ✓ | W12: =IF(V12="✓",COUNTIF($V$2:V12,"✓"),"") -> 11 | X12: https://cedrat-technologies.com/produit/apa120ml/
A13: Amplified Piezo Actuators (APA) | B13: 放大型压电促动器 | C13: APA100M | D13: Amplified Piezo Actuator | E13: 放大型压电促动器 | F13: 压电促动器、压电陶瓷驱动器、压电作动器、压电致动器、压电陶瓷执行器、放大式压电促动器、柔性铰链放大压电 | G13: 125 | H13: µm | I13: =IF(H13="mrad",ROUND(G13*180/PI()/1000,2)&"°",IF(H13="µm",G13/1000&" mm","")) -> 0.125 mm | J13: 230 | K13: 阻挡力 | L13: 1.9 | M13: 1910 | N13: 2.2 | Q13: 应变片闭环，无磁外壳，真空兼容 | R13: 标准品 | S13: Applications: Fast X-ray vacuum compatible shutters – dynamic valves – laser cavity tuning – miniature active flaps for aero vehicles | T13: 打开 | U13: PDF | V13: =IF(AND(OR('选型速查 Spec Match'!$C$4="全部 All",B13='选型速查 Spec Match'!$C$4),OR('选型速查 Spec Match'!$C$5="",AND(H13='选型速查 Spec Match'!$C$6,N(G13)>='选型速查 Spec Match'!$C$5)),OR('选型速查 Spec Match'!$C$7="",N(J13)>='选型速查 Spec Match'!$C$7),OR('选型速查 Spec Match'!$C$8="",N(M13)>='选型速查 Spec Match'!$C$8)),"✓","") -> ✓ | W13: =IF(V13="✓",COUNTIF($V$2:V13,"✓"),"") -> 12 | X13: https://cedrat-technologies.com/produit/apa100m/
... A42: Parallel Pre-stressed Actuators (PPA) | B42: 预紧式压电叠堆促动器 | C42: PPA120XL | D42: Parallel Pre-Stressed Actuator | E42: 预紧式压电叠堆促动器 | F42: 压电叠堆、压电陶瓷堆、叠层压电陶瓷、预紧压电陶瓷、压电陶瓷促动器、压电堆栈 | G42: 130 | H42: µm | I42: =IF(H42="mrad",ROUND(G42*180/PI()/1000,2)&"°",IF(H42="µm",G42/1000&" mm","")) -> 0.13 mm | J42: 7000 | K42: 阻挡力 | L42: 53.8 | M42: 3250 | N42: 51 | Q42: 应变片闭环，无磁外壳，真空兼容 | R42: 标准品 | S42: Applications: Stabilisation of heavy loads in precision machine tool – Fretting fatigue testing – High frequency shakers | T42: 打开 | U42: PDF | V42: =IF(AND(OR('选型速查 Spec Match'!$C$4="全部 All",B42='选型速查 Spec Match'!$C$4),OR('选型速查 Spec Match'!$C$5="",AND(H42='选型速查 Spec Match'!$C$6,N(G42)>='选型速查 Spec Match'!$C$5)),OR('选型速查 Spec Match'!$C$7="",N(J42)>='选型速查 Spec Match'!$C$7),OR('选型速查 Spec Match'!$C$8="",N(M42)>='选型速查 Spec Match'!$C$8)),"✓","") -> ✓ | W42: =IF(V42="✓",COUNTIF($V$2:V42,"✓"),"") -> 41 | X42: https://cedrat-technologies.com/produit/ppa120xl/
A43: Piezo Stages | B43: 压电纳米位移台 | C43: XY25XS | D43: Piezo Stage | E43: XY 二维压电位移台 | F43: 压电位移台、纳米位移台、纳米定位台、压电扫描台、压电平台、XY压电台、XYZ纳米平台、柔性铰链位移台、纳米定位系统 | G43: 25 | H43: µm | I43: =IF(H43="mrad",ROUND(G43*180/PI()/1000,2)&"°",IF(H43="µm",G43/1000&" mm","")) -> 0.025 mm | M43: 3000 | O43: 50mm550mm*19mm | P43: 响应时间 0,17ms | Q43: 应变片闭环，真空兼容 | R43: 标准品 | S43: The piezoelectric stage XY25XS is based on the APA 25XS actuators. The compact XY25XS stage is well suited to integrated devices for fiber positioning, micro scanning. | T43: 打开 | U43: PDF | V43: =IF(AND(OR('选型速查 Spec Match'!$C$4="全部 All",B43='选型速查 Spec Match'!$C$4),OR('选型速查 Spec Match'!$C$5="",AND(H43='选型速查 Spec Match'!$C$6,N(G43)>='选型速查 Spec Match'!$C$5)),OR('选型速查 Spec Match'!$C$7="",N(J43)>='选型速查 Spec Match'!$C$7),OR('选型速查 Spec Match'!$C$8="",N(M43)>='选型速查 Spec Match'!$C$8)),"✓","") -> ✓ | W43: =IF(V43="✓",COUNTIF($V$2:V43,"✓"),"") -> 42 | X43: https://cedrat-technologies.com/produit/xy25xs/
A44: Piezo Stages | B44: 压电纳米位移台 | C44: X60S | D44: Piezo Stage | E44: 单轴压电位移台 | F44: 压电位移台、纳米位移台、纳米定位台、压电扫描台、压电平台、XY压电台、XYZ纳米平台、柔性铰链位移台、纳米定位系统 | G44: 55 | H44: µm | I44: =IF(H44="mrad",ROUND(G44*180/PI()/1000,2)&"°",IF(H44="µm",G44/1000&" mm","")) -> 0.055 mm | M44: 1840 | O44: 30mm*30mm*12mm | P44: 响应时间 0,27 ms | Q44: 应变片闭环，真空兼容 | R44: 原型 | S44: The piezoelectric stage X60S has a stroke up to 110µm along the X axis and can be equipped with strain gauges for a very fine accuracy up to 10 nm. | T44: 打开 | U44: PDF | V44: =IF(AND(OR('选型速查 Spec Match'!$C$4="全部 All",B44='选型速查 Spec Match'!$C$4),OR('选型速查 Spec Match'!$C$5="",AND(H44='选型速查 Spec Match'!$C$6,N(G44)>='选型速查 Spec Match'!$C$5)),OR('选型速查 Spec Match'!$C$7="",N(J44)>='选型速查 Spec Match'!$C$7),OR('选型速查 Spec Match'!$C$8="",N(M44)>='选型速查 Spec Match'!$C$8)),"✓","") -> ✓ | W44: =IF(V44="✓",COUNTIF($V$2:V44,"✓"),"") -> 43 | X44: https://cedrat-technologies.com/produit/x60s/
A45: Piezo Stages | B45: 压电纳米位移台 | C45: X120S | D45: Piezo Stage | E45: 单轴压电位移台 | F45: 压电位移台、纳米位移台、纳米定位台、压电扫描台、压电平台、XY压电台、XYZ纳米平台、柔性铰链位移台、纳米定位系统 | G45: 110 | H45: µm | I45: =IF(H45="mrad",ROUND(G45*180/PI()/1000,2)&"°",IF(H45="µm",G45/1000&" mm","")) -> 0.11 mm | M45: 850 | O45: 30mm*30mm*12mm | P45: 响应时间 0,59 ms | Q45: 应变片闭环，真空兼容 | R45: 原型 | S45: The piezoelectric stage X120S has a stroke up to 110µm along the X axis and can be equipped with strain gauges for a very fine accuracy up to 10 nm. | T45: 打开 | U45: PDF | V45: =IF(AND(OR('选型速查 Spec Match'!$C$4="全部 All",B45='选型速查 Spec Match'!$C$4),OR('选型速查 Spec Match'!$C$5="",AND(H45='选型速查 Spec Match'!$C$6,N(G45)>='选型速查 Spec Match'!$C$5)),OR('选型速查 Spec Match'!$C$7="",N(J45)>='选型速查 Spec Match'!$C$7),OR('选型速查 Spec Match'!$C$8="",N(M45)>='选型速查 Spec Match'!$C$8)),"✓","") -> ✓ | W45: =IF(V45="✓",COUNTIF($V$2:V45,"✓"),"") -> 44 | X45: https://cedrat-technologies.com/produit/x120s/
A46: Piezo Stages | B46: 压电纳米位移台 | C46: XY200M | D46: Piezo Stage | E46: XY 二维压电位移台 | F46: 压电位移台、纳米位移台、纳米定位台、压电扫描台、压电平台、XY压电台、XYZ纳米平台、柔性铰链位移台、纳米定位系统 | G46: 200 | H46: µm | I46: =IF(H46="mrad",ROUND(G46*180/PI()/1000,2)&"°",IF(H46="µm",G46/1000&" mm","")) -> 0.2 mm | M46: 580 | O46: 100mm*100mm*22mm | P46: 响应时间 0,86 ms | Q46: 应变片闭环，真空兼容 | R46: 标准品 | S46: The piezoelectric stage XY200M is based on the APA 200M actuators and posseses a high stiffness. Applications include mask positioning, atomic force or scanning tunneling microscopes. | T46: 打开 | U46: PDF | V46: =IF(AND(OR('选型速查 Spec Match'!$C$4="全部 All",B46='选型速查 Spec Match'!$C$4),OR('选型速查 Spec Match'!$C$5="",AND(H46='选型速查 Spec Match'!$C$6,N(G46)>='选型速查 Spec Match'!$C$5)),OR('选型速查 Spec Match'!$C$7="",N(J46)>='选型速查 Spec Match'!$C$7),OR('选型速查 Spec Match'!$C$8="",N(M46)>='选型速查 Spec Match'!$C$8)),"✓","") -> ✓ | W46: =IF(V46="✓",COUNTIF($V$2:V46,"✓"),"") -> 45 | X46: https://cedrat-technologies.com/produit/xy200m/
A47: Piezo Stages | B47: 压电纳米位移台 | C47: XYZ200M | D47: Piezo Stage | E47: XYZ 三维压电位移台 | F47: 压电位移台、纳米位移台、纳米定位台、压电扫描台、压电平台、XY压电台、XYZ纳米平台、柔性铰链位移台、纳米定位系统 | G47: 200 | H47: µm | I47: =IF(H47="mrad",ROUND(G47*180/PI()/1000,2)&"°",IF(H47="µm",G47/1000&" mm","")) -> 0.2 mm | M47: 380 | O47: 100mm*100mm*49mm | P47: 响应时间 1,32 ms | Q47: 应变片闭环，真空兼容 | R47: 标准品 | S47: The piezoelectric stage XYZ200M is based on APA 200M actuators and posseses a high stiffness. Applications include confocal microscopy, mask positioning, inspection. | T47: 打开 | U47: PDF | V47: =IF(AND(OR('选型速查 Spec Match'!$C$4="全部 All",B47='选型速查 Spec Match'!$C$4),OR('选型速查 Spec Match'!$C$5="",AND(H47='选型速查 Spec Match'!$C$6,N(G47)>='选型速查 Spec Match'!$C$5)),OR('选型速查 Spec Match'!$C$7="",N(J47)>='选型速查 Spec Match'!$C$7),OR('选型速查 Spec Match'!$C$8="",N(M47)>='选型速查 Spec Match'!$C$8)),"✓","") -> ✓ | W47: =IF(V47="✓",COUNTIF($V$2:V47,"✓"),"") -> 46 | X47: https://cedrat-technologies.com/produit/xyz200m/
A48: Fast Piezo Shutters | B48: 压电快门 | C48: Cable for Shutters | D48: Shutter accessory | E48: 快门连接线缆（配件） | F48: 压电快门、快速光闸、高速快门、X射线快门、光束快门、真空快门 | I48: =IF(H48="mrad",ROUND(G48*180/PI()/1000,2)&"°",IF(H48="µm",G48/1000&" mm","")) | P48: 长度 150 cm；接头1 SUB-D9 Femelle；接头2 3 LEMO connectors | R48: 标准品 | S48: This cable is designed to connect the CTEC shutters with the Electronics Rack . | T48: 打开 | U48: PDF | V48: =IF(AND(OR('选型速查 Spec Match'!$C$4="全部 All",B48='选型速查 Spec Match'!$C$4),OR('选型速查 Spec Match'!$C$5="",AND(H48='选型速查 Spec Match'!$C$6,N(G48)>='选型速查 Spec Match'!$C$5)),OR('选型速查 Spec Match'!$C$7="",N(J48)>='选型速查 Spec Match'!$C$7),OR('选型速查 Spec Match'!$C$8="",N(M48)>='选型速查 Spec Match'!$C$8)),"✓","") -> ✓ | W48: =IF(V48="✓",COUNTIF($V$2:V48,"✓"),"") -> 47 | X48: https://cedrat-technologies.com/produit/cable-for-shutters/
A49: Fast Piezo Shutters | B49: 压电快门 | C49: FAPS400M | D49: Fast Amplified Piezo Shutter | E49: 大孔径 X 射线压电快门 | F49: 压电快门、快速光闸、高速快门、X射线快门、光束快门、真空快门 | I49: =IF(H49="mrad",ROUND(G49*180/PI()/1000,2)&"°",IF(H49="µm",G49/1000&" mm","")) | O49: 73mm*54mm*65mm | P49: 最大光束直径 3,0 mm；开/关时间 8 ms；质量 152 g | Q49: 超高真空兼容 | R49: 标准品 | S49: The FAPS400M is a fast shutter for X-ray beam offering the largest aperture of the Cedrat Technologies Shutters family with a stroke higher than 3mm and a short response time lower than 8ms. It is built with 2 APA400M activating a mechanical amplifier or “lever arm”. All the FAPS400M include tungste | T49: 打开 | U49: PDF | V49: =IF(AND(OR('选型速查 Spec Match'!$C$4="全部 All",B49='选型速查 Spec Match'!$C$4),OR('选型速查 Spec Match'!$C$5="",AND(H49='选型速查 Spec Match'!$C$6,N(G49)>='选型速查 Spec Match'!$C$5)),OR('选型速查 Spec Match'!$C$7="",N(J49)>='选型速查 Spec Match'!$C$7),OR('选型速查 Spec Match'!$C$8="",N(M49)>='选型速查 Spec Match'!$C$8)),"✓","") -> ✓ | W49: =IF(V49="✓",COUNTIF($V$2:V49,"✓"),"") -> 48 | X49: https://cedrat-technologies.com/produit/faps400m/
A50: Fast Piezo Shutters | B50: 压电快门 | C50: FPS400M | D50: Fast Piezo Shutter | E50: 压电快门 | F50: 压电快门、快速光闸、高速快门、X射线快门、光束快门、真空快门 | I50: =IF(H50="mrad",ROUND(G50*180/PI()/1000,2)&"°",IF(H50="µm",G50/1000&" mm","")) | O50: 60mm*44mm*21mm | P50: 最大光束直径 0,7 mm；开/关时间 4 ms；质量 84 g | Q50: 超高真空兼容 | R50: 标准品 | S50: The FPS400M (derived from FPS200M) is based on standard amplified piezo actuators APA 400M with a special optical head. The FPS400M is a compact, low jitter and high stroke shutter solution. Tungsten optical teeth are included. | T50: 打开 | U50: PDF | V50: =IF(AND(OR('选型速查 Spec Match'!$C$4="全部 All",B50='选型速查 Spec Match'!$C$4),OR('选型速查 Spec Match'!$C$5="",AND(H50='选型速查 Spec Match'!$C$6,N(G50)>='选型速查 Spec Match'!$C$5)),OR('选型速查 Spec Match'!$C$7="",N(J50)>='选型速查 Spec Match'!$C$7),OR('选型速查 Spec Match'!$C$8="",N(M50)>='选型速查 Spec Match'!$C$8)),"✓","") -> ✓ | W50: =IF(V50="✓",COUNTIF($V$2:V50,"✓"),"") -> 49 | X50: https://cedrat-technologies.com/produit/fps400m/
A51: Fast Piezo Shutters | B51: 压电快门 | C51: FPS900M | D51: Fast Piezo Shutter | E51: 压电快门 | F51: 压电快门、快速光闸、高速快门、X射线快门、光束快门、真空快门 | I51: =IF(H51="mrad",ROUND(G51*180/PI()/1000,2)&"°",IF(H51="µm",G51/1000&" mm","")) | O51: 60mm*44mm*23mm | P51: 最大光束直径 1,1 mm；开/关时间 10 ms；质量 82 g | Q51: 超高真空兼容 | R51: 按需定制 | S51: The FPS900M (derived from FPS400M) is based on customized amplified piezo actuators APA900M with a special optical head. The FPS900M is a compact, low jitter and high stroke shutter solution. Tungsten optical teeth are included. | T51: 打开 | U51: PDF | V51: =IF(AND(OR('选型速查 Spec Match'!$C$4="全部 All",B51='选型速查 Spec Match'!$C$4),OR('选型速查 Spec Match'!$C$5="",AND(H51='选型速查 Spec Match'!$C$6,N(G51)>='选型速查 Spec Match'!$C$5)),OR('选型速查 Spec Match'!$C$7="",N(J51)>='选型速查 Spec Match'!$C$7),OR('选型速查 Spec Match'!$C$8="",N(M51)>='选型速查 Spec Match'!$C$8)),"✓","") -> ✓ | W51: =IF(V51="✓",COUNTIF($V$2:V51,"✓"),"") -> 50 | X51: https://cedrat-technologies.com/produit/fps900m/
A52: Fast Piezo Shutters | B52: 压电快门 | C52: Vacuum Box | D52: Shutter accessory | E52: 快门真空盒（配件） | F52: 压电快门、快速光闸、高速快门、X射线快门、光束快门、真空快门 | I52: =IF(H52="mrad",ROUND(G52*180/PI()/1000,2)&"°",IF(H52="µm",G52/1000&" mm","")) | O52: 93mm*105mm*144mm | P52: 真空接口 KF40；质量 1,3 Kg | R52: 标准品 | S52: CTEC has developed a fully integrated solution for FPS and FAPS products in Vacuum Environments. The Shutter is mounted inside the Box with vacuum cable feedtrought. The shutter can be unmounted and mounted again without removing the Vacuum Box from the beamline. | T52: 打开 | U52: PDF | V52: =IF(AND(OR('选型速查 Spec Match'!$C$4="全部 All",B52='选型速查 Spec Match'!$C$4),OR('选型速查 Spec Match'!$C$5="",AND(H52='选型速查 Spec Match'!$C$6,N(G52)>='选型速查 Spec Match'!$C$5)),OR('选型速查 Spec Match'!$C$7="",N(J52)>='选型速查 Spec Match'!$C$7),OR('选型速查 Spec Match'!$C$8="",N(M52)>='选型速查 Spec Match'!$C$8)),"✓","") -> ✓ | W52: =IF(V52="✓",COUNTIF($V$2:V52,"✓"),"") -> 51 | X52: https://cedrat-technologies.com/produit/vacuum-box/
A53: Stepping Piezo Actuators (piezo motors) | B53: 步进压电电机（压电马达） | C53: FSPA35XS | D53: Fine Stepping Piezo Actuator | E53: 精细步进压电电机（带减速） | F53: 压电电机、压电马达、压电直线电机、步进压电电机、惯性压电电机、粘滑压电驱动器、压电旋转电机、无磁电机、MRI兼容电机 | G53: 5 | H53: mm | I53: =IF(H53="mrad",ROUND(G53*180/PI()/1000,2)&"°",IF(H53="µm",G53/1000&" mm","")) | J53: 100 | K53: 驱动力 | P53: 典型寿命 100 cycles | Q53: 微/纳定位，锁止机构 | R53: 预发布 | S53: Fine Stepping Piezo Actuator (FSPA35XS) is a patented actuator that combines SPA technology with mechanical reduction. Step sizes lower than 100nm are achievable in fine displacement. Typical max speed for this FSPA is 200 um/s. | T53: 打开 | U53: PDF | V53: =IF(AND(OR('选型速查 Spec Match'!$C$4="全部 All",B53='选型速查 Spec Match'!$C$4),OR('选型速查 Spec Match'!$C$5="",AND(H53='选型速查 Spec Match'!$C$6,N(G53)>='选型速查 Spec Match'!$C$5)),OR('选型速查 Spec Match'!$C$7="",N(J53)>='选型速查 Spec Match'!$C$7),OR('选型速查 Spec Match'!$C$8="",N(M53)>='选型速查 Spec Match'!$C$8)),"✓","") -> ✓ | W53: =IF(V53="✓",COUNTIF($V$2:V53,"✓"),"") -> 52 | X53: https://cedrat-technologies.com/produit/fspa35xs/
A54: Stepping Piezo Actuators (piezo motors) | B54: 步进压电电机（压电马达） | C54: LSPA30uXS | D54: Linear Stepping Piezo Actuator | E54: 微型直线压电电机 | F54: 压电电机、压电马达、压电直线电机、步进压电电机、惯性压电电机、粘滑压电驱动器、压电旋转电机、无磁电机、MRI兼容电机 | G54: 6 | H54: mm | I54: =IF(H54="mrad",ROUND(G54*180/PI()/1000,2)&"°",IF(H54="µm",G54/1000&" mm","")) | J54: 0.3 | K54: 驱动力 | P54: 质量 1,9 g；最大速度 70 mm/s | Q54: 无磁，MRI兼容 | R54: 原型 | S54: The Linear Stepping Piezo Actuator LSPA30uXS is a high-force density stepping linear micro piezomotor. | T54: 打开 | U54: PDF | V54: =IF(AND(OR('选型速查 Spec Match'!$C$4="全部 All",B54='选型速查 Spec Match'!$C$4),OR('选型速查 Spec Match'!$C$5="",AND(H54='选型速查 Spec Match'!$C$6,N(G54)>='选型速查 Spec Match'!$C$5)),OR('选型速查 Spec Match'!$C$7="",N(J54)>='选型速查 Spec Match'!$C$7),OR('选型速查 Spec Match'!$C$8="",N(M54)>='选型速查 Spec Match'!$C$8)),"✓","") -> ✓ | W54: =IF(V54="✓",COUNTIF($V$2:V54,"✓"),"") -> 53 | X54: https://cedrat-technologies.com/produit/lspa30uxs/
A55: Stepping Piezo Actuators (piezo motors) | B55: 步进压电电机（压电马达） | C55: LSPA35XS | D55: Linear Stepping Piezo Actuator | E55: 直线压电电机 | F55: 压电电机、压电马达、压电直线电机、步进压电电机、惯性压电电机、粘滑压电驱动器、压电旋转电机、无磁电机、MRI兼容电机 | G55: 10 | H55: mm | I55: =IF(H55="mrad",ROUND(G55*180/PI()/1000,2)&"°",IF(H55="µm",G55/1000&" mm","")) | J55: 1 | K55: 驱动力 | P55: 质量 5 g；最大速度 30 mm/s | Q55: 无磁 | R55: 原型 | S55: The Linear Stepping Piezo Actuator LSPA35XS is a high-force density stepping linear micro piezomotor. | T55: 打开 | U55: PDF | V55: =IF(AND(OR('选型速查 Spec Match'!$C$4="全部 All",B55='选型速查 Spec Match'!$C$4),OR('选型速查 Spec Match'!$C$5="",AND(H55='选型速查 Spec Match'!$C$6,N(G55)>='选型速查 Spec Match'!$C$5)),OR('选型速查 Spec Match'!$C$7="",N(J55)>='选型速查 Spec Match'!$C$7),OR('选型速查 Spec Match'!$C$8="",N(M55)>='选型速查 Spec Match'!$C$8)),"✓","") -> ✓ | W55: =IF(V55="✓",COUNTIF($V$2:V55,"✓"),"") -> 54 | X55: https://cedrat-technologies.com/produit/lspa35xs/
A56: Stepping Piezo Actuators (piezo motors) | B56: 步进压电电机（压电马达） | C56: MSPA30uXS | D56: Modular Stepping Piezo Actuator | E56: 模块化压电电机（直线/旋转） | F56: 压电电机、压电马达、压电直线电机、步进压电电机、惯性压电电机、粘滑压电驱动器、压电旋转电机、无磁电机、MRI兼容电机 | I56: =IF(H56="mrad",ROUND(G56*180/PI()/1000,2)&"°",IF(H56="µm",G56/1000&" mm","")) | J56: 0.3 | K56: 驱动力 | P56: 体积 2 cm³；最大速度 50 mm/s；寿命 >2 Km | Q56: 无磁，真空兼容 | R56: 预发布 | S56: MSPA is a module that provides unlimited motion in both rotation and translation. Since it’s a module it easily fits any existing devices requiring 0.3 N of driving force. | T56: 打开 | U56: PDF | V56: =IF(AND(OR('选型速查 Spec Match'!$C$4="全部 All",B56='选型速查 Spec Match'!$C$4),OR('选型速查 Spec Match'!$C$5="",AND(H56='选型速查 Spec Match'!$C$6,N(G56)>='选型速查 Spec Match'!$C$5)),OR('选型速查 Spec Match'!$C$7="",N(J56)>='选型速查 Spec Match'!$C$7),OR('选型速查 Spec Match'!$C$8="",N(M56)>='选型速查 Spec Match'!$C$8)),"✓","") -> ✓ | W56: =IF(V56="✓",COUNTIF($V$2:V56,"✓"),"") -> 55 | X56: https://cedrat-technologies.com/produit/mspa30uxs/
A57: Stepping Piezo Actuators (piezo motors) | B57: 步进压电电机（压电马达） | C57: MSPA35XS | D57: Modular Stepping Piezo Actuator | E57: 模块化压电电机（直线/旋转） | F57: 压电电机、压电马达、压电直线电机、步进压电电机、惯性压电电机、粘滑压电驱动器、压电旋转电机、无磁电机、MRI兼容电机 | I57: =IF(H57="mrad",ROUND(G57*180/PI()/1000,2)&"°",IF(H57="µm",G57/1000&" mm","")) | J57: 1 | K57: 驱动力 | P57: 体积 7 cm³；最大速度 20 mm/s；寿命 >2 Km | Q57: 无磁，真空兼容 | R57: 预发布 | S57: MSPA is a module that provides unlimited motion in both rotation and translation. Since it’s a module it easily fits any existing devices requiring 1 N of driving force. | T57: 打开 | U57: PDF | V57: =IF(AND(OR('选型速查 Spec Match'!$C$4="全部 All",B57='选型速查 Spec Match'!$C$4),OR('选型速查 Spec Match'!$C$5="",AND(H57='选型速查 Spec Match'!$C$6,N(G57)>='选型速查 Spec Match'!$C$5)),OR('选型速查 Spec Match'!$C$7="",N(J57)>='选型速查 Spec Match'!$C$7),OR('选型速查 Spec Match'!$C$8="",N(M57)>='选型速查 Spec Match'!$C$8)),"✓","") -> ✓ | W57: =IF(V57="✓",COUNTIF($V$2:V57,"✓"),"") -> 56 | X57: https://cedrat-technologies.com/produit/mspa35xs/
A58: Stepping Piezo Actuators (piezo motors) | B58: 步进压电电机（压电马达） | C58: MSPA40SM | D58: Modular Stepping Piezo Actuator | E58: 模块化压电电机（直线/旋转） | F58: 压电电机、压电马达、压电直线电机、步进压电电机、惯性压电电机、粘滑压电驱动器、压电旋转电机、无磁电机、MRI兼容电机 | I58: =IF(H58="mrad",ROUND(G58*180/PI()/1000,2)&"°",IF(H58="µm",G58/1000&" mm","")) | J58: 2.5 | K58: 驱动力 | P58: 体积 20 cm³；最大速度 10 mm/s；寿命 >2 Km | Q58: 无磁，真空兼容 | R58: 预发布 | S58: MSPA is a module that provides unlimited motion in both rotation and translation. Since it’s a module it easily fits any existing devices requiring 25 N of driving force. | T58: 打开 | U58: PDF | V58: =IF(AND(OR('选型速查 Spec Match'!$C$4="全部 All",B58='选型速查 Spec Match'!$C$4),OR('选型速查 Spec Match'!$C$5="",AND(H58='选型速查 Spec Match'!$C$6,N(G58)>='选型速查 Spec Match'!$C$5)),OR('选型速查 Spec Match'!$C$7="",N(J58)>='选型速查 Spec Match'!$C$7),OR('选型速查 Spec Match'!$C$8="",N(M58)>='选型速查 Spec Match'!$C$8)),"✓","") -> ✓ | W58: =IF(V58="✓",COUNTIF($V$2:V58,"✓"),"") -> 57 | X58: https://cedrat-technologies.com/produit/mspa40sm/
A59: Stepping Piezo Actuators (piezo motors) | B59: 步进压电电机（压电马达） | C59: RSPA30XS | D59: Rotary Stepping Piezo Actuator | E59: 旋转压电电机 | F59: 压电电机、压电马达、压电直线电机、步进压电电机、惯性压电电机、粘滑压电驱动器、压电旋转电机、无磁电机、MRI兼容电机 | H59: 旋转（不限角度） | I59: =IF(H59="mrad",ROUND(G59*180/PI()/1000,2)&"°",IF(H59="µm",G59/1000&" mm","")) | P59: 质量 3 g；最大速度 65 rpm；最大驱动力 1,33 Nmm | R59: 预发布 | S59: Rotary Stepping Piezoelectric Actuators (RSPA) are new long-stroke rotating piezoelectric motors for micro/nano positioning applications benefiting from the APA® heritage. They operate by accumulation of small steps. | T59: 打开 | U59: PDF | V59: =IF(AND(OR('选型速查 Spec Match'!$C$4="全部 All",B59='选型速查 Spec Match'!$C$4),OR('选型速查 Spec Match'!$C$5="",AND(H59='选型速查 Spec Match'!$C$6,N(G59)>='选型速查 Spec Match'!$C$5)),OR('选型速查 Spec Match'!$C$7="",N(J59)>='选型速查 Spec Match'!$C$7),OR('选型速查 Spec Match'!$C$8="",N(M59)>='选型速查 Spec Match'!$C$8)),"✓","") -> ✓ | W59: =IF(V59="✓",COUNTIF($V$2:V59,"✓"),"") -> 58 | X59: https://cedrat-technologies.com/produit/rspa30xs/
A60: Stepping Piezo Stages | B60: 压电电机直线位移台 | C60: LSPS35XS | D60: Linear Stepping Piezo Stage | E60: 压电电机直线位移台 | F60: 压电电机位移台、压电直线台、长行程纳米位移台、纳米步进台 | G60: 10 | H60: mm | I60: =IF(H60="mrad",ROUND(G60*180/PI()/1000,2)&"°",IF(H60="µm",G60/1000&" mm","")) | J60: 1 | K60: 驱动力 | O60: 30mm*30mm | P60: 最大速度 30 mm/s | R60: 原型 | S60: The Linear Stepping Piezo Stage LSPS35XS is based on the Stepping Piezo Actuator’s principle. It provides both long stroke and micro positioning resolution. | T60: 打开 | U60: PDF | V60: =IF(AND(OR('选型速查 Spec Match'!$C$4="全部 All",B60='选型速查 Spec Match'!$C$4),OR('选型速查 Spec Match'!$C$5="",AND(H60='选型速查 Spec Match'!$C$6,N(G60)>='选型速查 Spec Match'!$C$5)),OR('选型速查 Spec Match'!$C$7="",N(J60)>='选型速查 Spec Match'!$C$7),OR('选型速查 Spec Match'!$C$8="",N(M60)>='选型速查 Spec Match'!$C$8)),"✓","") -> ✓ | W60: =IF(V60="✓",COUNTIF($V$2:V60,"✓"),"") -> 59 | X60: https://cedrat-technologies.com/produit/lsps35xs/
A61: Stepping Piezo Stages | B61: 压电电机直线位移台 | C61: LSPS40SM | D61: Linear Stepping Piezo Stage | E61: 压电电机直线位移台 | F61: 压电电机位移台、压电直线台、长行程纳米位移台、纳米步进台 | G61: 10 | H61: mm | I61: =IF(H61="mrad",ROUND(G61*180/PI()/1000,2)&"°",IF(H61="µm",G61/1000&" mm","")) | J61: 1 | K61: 驱动力 | O61: 30mm*30mm | P61: 最大速度 30 mm/s | R61: 预发布 | S61: The Linear Stepping Piezo Stage LSPS40SM is based on the Stepping Piezo Actuator’s principle. It provides both long stroke and micro positioning resolution. | T61: 打开 | U61: PDF | V61: =IF(AND(OR('选型速查 Spec Match'!$C$4="全部 All",B61='选型速查 Spec Match'!$C$4),OR('选型速查 Spec Match'!$C$5="",AND(H61='选型速查 Spec Match'!$C$6,N(G61)>='选型速查 Spec Match'!$C$5)),OR('选型速查 Spec Match'!$C$7="",N(J61)>='选型速查 Spec Match'!$C$7),OR('选型速查 Spec Match'!$C$8="",N(M61)>='选型速查 Spec Match'!$C$8)),"✓","") -> ✓ | W61: =IF(V61="✓",COUNTIF($V$2:V61,"✓"),"") -> 60 | X61: https://cedrat-technologies.com/produit/lsps40sm/
A62: Piezo Motor Controllers | B62: 压电电机控制器 | C62: SPC45 | D62: Stepping Piezo Controller | E62: 步进压电电机控制板 | F62: 压电电机控制器、压电马达驱动器 | I62: =IF(H62="mrad",ROUND(G62*180/PI()/1000,2)&"°",IF(H62="µm",G62/1000&" mm","")) | P62: 控制通道数 1；最大输出电流 5mA | S62: The Stepping Piezo Controller SPC45 is the driver board of the SPA30uXS. It includes control functions, numerical and analogical interfaces and serial communication ports. The SPC45 is powered with the provided standard AC/DC converter (12V to 24V). | T62: 打开 | U62: PDF | V62: =IF(AND(OR('选型速查 Spec Match'!$C$4="全部 All",B62='选型速查 Spec Match'!$C$4),OR('选型速查 Spec Match'!$C$5="",AND(H62='选型速查 Spec Match'!$C$6,N(G62)>='选型速查 Spec Match'!$C$5)),OR('选型速查 Spec Match'!$C$7="",N(J62)>='选型速查 Spec Match'!$C$7),OR('选型速查 Spec Match'!$C$8="",N(M62)>='选型速查 Spec Match'!$C$8)),"✓","") -> ✓ | W62: =IF(V62="✓",COUNTIF($V$2:V62,"✓"),"") -> 61 | X62: https://cedrat-technologies.com/produit/spc45/
A63: Fast Steering Mirrors (FSM) | B63: 快速反射镜（快反镜） | C63: P-FSM150S | D63: Piezoelectric Fast Steering Mirror | E63: 压电快反镜 | F63: 快反镜、快速反射镜、快速控制反射镜、快速偏转镜、快速倾斜镜、精跟踪镜、精瞄镜、指向镜、FSM | G63: 18 | H63: mrad | I63: =IF(H63="mrad",ROUND(G63*180/PI()/1000,2)&"°",IF(H63="µm",G63/1000&" mm","")) -> 1.03° | M63: 700 | O63: 61mm*63mm*H30mm | R63: 标准品 | S63: The P-FSM150S is a piezo based Fast Steering Mirror of +15 mm diameter clear aperture (in SiC, metallic or glass substrate) with +18 mrad angular stroke. The P-FSM150S is equipped with Strain Gages positioning sensor for accurate positioning control. The P-FSM150S has been qualified for Space enviro | T63: 打开 | U63: PDF | V63: =IF(AND(OR('选型速查 Spec Match'!$C$4="全部 All",B63='选型速查 Spec Match'!$C$4),OR('选型速查 Spec Match'!$C$5="",AND(H63='选型速查 Spec Match'!$C$6,N(G63)>='选型速查 Spec Match'!$C$5)),OR('选型速查 Spec Match'!$C$7="",N(J63)>='选型速查 Spec Match'!$C$7),OR('选型速查 Spec Match'!$C$8="",N(M63)>='选型速查 Spec Match'!$C$8)),"✓","") -> ✓ | W63: =IF(V63="✓",COUNTIF($V$2:V63,"✓"),"") -> 62 | X63: https://cedrat-technologies.com/produit/p-fsm150s/
A64: Fast Steering Mirrors (FSM) | B64: 快速反射镜（快反镜） | C64: M-FSM45 | D64: Magnetic Fast Steering Mirror | E64: 磁驱快反镜 | F64: 快反镜、快速反射镜、快速控制反射镜、快速偏转镜、快速倾斜镜、精跟踪镜、精瞄镜、指向镜、FSM | G64: 50 | H64: mrad | I64: =IF(H64="mrad",ROUND(G64*180/PI()/1000,2)&"°",IF(H64="µm",G64/1000&" mm","")) -> 2.86° | M64: 100 | O64: Ø45mm*40mm | R64: 标准品 | S64: The M-FSM45 is a Magnetic based Fast Steering Mirror of +15 mm diameter clear aperture (in SiC, metallic or glass substrate) with +50 mrad angular stroke. The M-FSM45 is equipped with Eddy Current positioning sensors (ECS) for accurate positioning control. It is space-qualified for free space optica | T64: 打开 | U64: PDF | V64: =IF(AND(OR('选型速查 Spec Match'!$C$4="全部 All",B64='选型速查 Spec Match'!$C$4),OR('选型速查 Spec Match'!$C$5="",AND(H64='选型速查 Spec Match'!$C$6,N(G64)>='选型速查 Spec Match'!$C$5)),OR('选型速查 Spec Match'!$C$7="",N(J64)>='选型速查 Spec Match'!$C$7),OR('选型速查 Spec Match'!$C$8="",N(M64)>='选型速查 Spec Match'!$C$8)),"✓","") -> ✓ | W64: =IF(V64="✓",COUNTIF($V$2:V64,"✓"),"") -> 63 | X64: https://cedrat-technologies.com/produit/m-fsm45/
A65: Fast Steering Mirrors (FSM) | B65: 快速反射镜（快反镜） | C65: M-FSM45-HPL | D65: Magnetic Fast Steering Mirror for High Power Laser | E65: 高功率激光用磁驱快反镜 | F65: 快反镜、快速反射镜、快速控制反射镜、快速偏转镜、快速倾斜镜、精跟踪镜、精瞄镜、指向镜、FSM | G65: 90 | H65: mrad | I65: =IF(H65="mrad",ROUND(G65*180/PI()/1000,2)&"°",IF(H65="µm",G65/1000&" mm","")) -> 5.16° | M65: 80 | O65: ⌀45 * 60mm | R65: 标准品 | S65: The M-FSM45-HPL is a Magnetic based Fast Steering Mirror for High Power Laser of +16 mm diameter clear aperture (in SiC, metallic or glass substrate) with +90 mrad angular stroke. The M-FSM45-HPL is equipped with Eddy Current positioning sensors (ECS) for accurate positioning control. It is space-qu | T65: 打开 | U65: PDF | V65: =IF(AND(OR('选型速查 Spec Match'!$C$4="全部 All",B65='选型速查 Spec Match'!$C$4),OR('选型速查 Spec Match'!$C$5="",AND(H65='选型速查 Spec Match'!$C$6,N(G65)>='选型速查 Spec Match'!$C$5)),OR('选型速查 Spec Match'!$C$7="",N(J65)>='选型速查 Spec Match'!$C$7),OR('选型速查 Spec Match'!$C$8="",N(M65)>='选型速查 Spec Match'!$C$8)),"✓","") -> ✓ | W65: =IF(V65="✓",COUNTIF($V$2:V65,"✓"),"") -> 64 | X65: https://cedrat-technologies.com/produit/m-fsm45-hpl/
A66: Fast Steering Mirrors (FSM) | B66: 快速反射镜（快反镜） | C66: M-FSM62 | D66: Magnetic Fast Steering Mirror | E66: 磁驱快反镜（大口径） | F66: 快反镜、快速反射镜、快速控制反射镜、快速偏转镜、快速倾斜镜、精跟踪镜、精瞄镜、指向镜、FSM | G66: 140 | H66: mrad | I66: =IF(H66="mrad",ROUND(G66*180/PI()/1000,2)&"°",IF(H66="µm",G66/1000&" mm","")) -> 8.02° | M66: 100 | O66: Ø62mm*60mm | R66: 标准品 | S66: The MFSM62 is a Magnetic based Fast Steering Mirror of +30 mm diameter clear aperture in SiC substrate with 140 mrad angular stroke in open loop and 120 mrad in closed loop. The MFSM62 can be equipped with Eddy Current positioning sensor (ECS) for accurate positioning control. | T66: 打开 | U66: PDF | V66: =IF(AND(OR('选型速查 Spec Match'!$C$4="全部 All",B66='选型速查 Spec Match'!$C$4),OR('选型速查 Spec Match'!$C$5="",AND(H66='选型速查 Spec Match'!$C$6,N(G66)>='选型速查 Spec Match'!$C$5)),OR('选型速查 Spec Match'!$C$7="",N(J66)>='选型速查 Spec Match'!$C$7),OR('选型速查 Spec Match'!$C$8="",N(M66)>='选型速查 Spec Match'!$C$8)),"✓","") -> ✓ | W66: =IF(V66="✓",COUNTIF($V$2:V66,"✓"),"") -> 65 | X66: https://cedrat-technologies.com/produit/m-fsm62/
A67: Fast Steering Platforms (tip-tilt) | B67: 压电偏摆台（Tip-Tilt 倾斜台） | C67: DTT15XS-SG | D67: Dynamic Tip-Tilt Mechanism | E67: 压电二维偏摆台（带应变闭环） | F67: 压电偏摆台、压电倾斜台、Tip-Tilt、二维偏转台、倾斜镜、摆镜、高速偏摆镜、压电偏转镜 | G67: 2 | H67: mrad | I67: =IF(H67="mrad",ROUND(G67*180/PI()/1000,2)&"°",IF(H67="µm",G67/1000&" mm","")) -> 0.11° | M67: 3000 | O67: 40mm*40mm*24mm | R67: 标准品 | S67: The Dynamic Tip Tilt DTT15XS-SG is a piezo based fast-steering platform able to rotate Fused Silica based mirror along 2 orthogonal axes with 2 mrad angular stroke. The DTT15XS-SG is equipped with Strain Gages positioning sensor & embedded conditioning board for accurate positioning control. The DTT | T67: 打开 | U67: PDF | V67: =IF(AND(OR('选型速查 Spec Match'!$C$4="全部 All",B67='选型速查 Spec Match'!$C$4),OR('选型速查 Spec Match'!$C$5="",AND(H67='选型速查 Spec Match'!$C$6,N(G67)>='选型速查 Spec Match'!$C$5)),OR('选型速查 Spec Match'!$C$7="",N(J67)>='选型速查 Spec Match'!$C$7),OR('选型速查 Spec Match'!$C$8="",N(M67)>='选型速查 Spec Match'!$C$8)),"✓","") -> ✓ | W67: =IF(V67="✓",COUNTIF($V$2:V67,"✓"),"") -> 66 | X67: https://cedrat-technologies.com/produit/dtt15xs-sg/
A68: Fast Steering Platforms (tip-tilt) | B68: 压电偏摆台（Tip-Tilt 倾斜台） | C68: DTT35XS-SG | D68: Dynamic Tip-Tilt Mechanism | E68: 压电二维偏摆台（带应变闭环） | F68: 压电偏摆台、压电倾斜台、Tip-Tilt、二维偏转台、倾斜镜、摆镜、高速偏摆镜、压电偏转镜 | G68: 5 | H68: mrad | I68: =IF(H68="mrad",ROUND(G68*180/PI()/1000,2)&"°",IF(H68="µm",G68/1000&" mm","")) -> 0.29° | M68: 2600 | O68: Ø45mm*22mm | R68: 标准品 | S68: The Dynamic Tip Tilt DTT35XS-SG is a piezo based fast-steering platform able to rotate Fused Silica based mirror along 2 orthogonal axes with 5 mrad angular stroke. The DTT35XS-SG is equipped with Strain Gages positioning sensor for accurate positioning control. The DTT35XS-SG is suitable for glass | T68: 打开 | U68: PDF | V68: =IF(AND(OR('选型速查 Spec Match'!$C$4="全部 All",B68='选型速查 Spec Match'!$C$4),OR('选型速查 Spec Match'!$C$5="",AND(H68='选型速查 Spec Match'!$C$6,N(G68)>='选型速查 Spec Match'!$C$5)),OR('选型速查 Spec Match'!$C$7="",N(J68)>='选型速查 Spec Match'!$C$7),OR('选型速查 Spec Match'!$C$8="",N(M68)>='选型速查 Spec Match'!$C$8)),"✓","") -> ✓ | W68: =IF(V68="✓",COUNTIF($V$2:V68,"✓"),"") -> 67 | X68: https://cedrat-technologies.com/produit/dtt35xs-sg/
...

Sheet 选型速查 Spec Match
B1: 选型速查：输入标讯的参数要求，下面列出符合的 Cedrat 型号 | L1: 全部 All
B2: 只改黄色格子。留空 = 不限制。行程要和单位一起填（例如 100 + µm，或 10 + mrad）。 | L2: 放大型压电促动器
L3: 预紧式压电叠堆促动器
B4: 类别 | C4: 全部 All | D4: 例：快反镜 → 选 "快速反射镜（快反镜）" | L4: 压电纳米位移台
B5: 最小行程 | D5: 例：标讯要求 "行程≥100µm"，填 100 | L5: 压电快门
B6: 行程单位 | C6: µm | D6: µm / mm / mrad | L6: 步进压电电机（压电马达）
B7: 最小出力 (N) | D7: APA/PPA 为阻挡力 | L7: 压电电机直线位移台
B8: 最小谐振频率 (Hz) | D8: 例：带宽≥1 kHz，填 1000 | L8: 压电电机控制器
L9: 快速反射镜（快反镜）
B10: 符合的型号数 | C10: =COUNTIF('产品表 Products'!$V$2:$V$105,"✓") -> 104 | L10: 压电偏摆台（Tip-Tilt 倾斜台）
L11: 磁驱直线作动器（动铁式）
B12: # | C12: 类别（中文） | D12: 型号 | E12: 中文名称 | F12: 行程 | G12: 单位 | H12: 出力 (N) | I12: 谐振 (Hz) | J12: 链接 | L12: 惯性作动器（主动减振）
B13: 1 | C13: =IFERROR(INDEX('产品表 Products'!$B$2:$B$105,MATCH(1,'产品表 Products'!$W$2:$W$105,0))&"","") -> 放大型压电促动器 | D13: =IFERROR(INDEX('产品表 Products'!$C$2:$C$105,MATCH(1,'产品表 Products'!$W$2:$W$105,0))&"","") -> APA30uXS | E13: =IFERROR(INDEX('产品表 Products'!$E$2:$E$105,MATCH(1,'产品表 Products'!$W$2:$W$105,0))&"","") -> 放大型压电促动器 | F13: =IFERROR(INDEX('产品表 Products'!$G$2:$G$105,MATCH(1,'产品表 Products'!$W$2:$W$105,0)),"") -> 34 | G13: =IFERROR(INDEX('产品表 Products'!$H$2:$H$105,MATCH(1,'产品表 Products'!$W$2:$W$105,0))&"","") -> µm | H13: =IFERROR(INDEX('产品表 Products'!$J$2:$J$105,MATCH(1,'产品表 Products'!$W$2:$W$105,0)),"") -> 3.7 | I13: =IFERROR(INDEX('产品表 Products'!$M$2:$M$105,MATCH(1,'产品表 Products'!$W$2:$W$105,0)),"") -> 4778 | J13: =IFERROR(HYPERLINK(INDEX('产品表 Products'!$X$2:$X$105,MATCH(1,'产品表 Products'!$W$2:$W$105,0)),"打开"),"") -> 打开 | L13: 磁驱作动器驱动器
B14: 2 | C14: =IFERROR(INDEX('产品表 Products'!$B$2:$B$105,MATCH(2,'产品表 Products'!$W$2:$W$105,0))&"","") -> 放大型压电促动器 | D14: =IFERROR(INDEX('产品表 Products'!$C$2:$C$105,MATCH(2,'产品表 Products'!$W$2:$W$105,0))&"","") -> APA35XS | E14: =IFERROR(INDEX('产品表 Products'!$E$2:$E$105,MATCH(2,'产品表 Products'!$W$2:$W$105,0))&"","") -> 放大型压电促动器 | F14: =IFERROR(INDEX('产品表 Products'!$G$2:$G$105,MATCH(2,'产品表 Products'!$W$2:$W$105,0)),"") -> 52 | G14: =IFERROR(INDEX('产品表 Products'!$H$2:$H$105,MATCH(2,'产品表 Products'!$W$2:$W$105,0))&"","") -> µm | H14: =IFERROR(INDEX('产品表 Products'!$J$2:$J$105,MATCH(2,'产品表 Products'!$W$2:$W$105,0)),"") -> 27 | I14: =IFERROR(INDEX('产品表 Products'!$M$2:$M$105,MATCH(2,'产品表 Products'!$W$2:$W$105,0)),"") -> 3880 | J14: =IFERROR(HYPERLINK(INDEX('产品表 Products'!$X$2:$X$105,MATCH(2,'产品表 Products'!$W$2:$W$105,0)),"打开"),"") -> 打开 | L14: 压电驱动放大器板卡
B15: 3 | C15: =IFERROR(INDEX('产品表 Products'!$B$2:$B$105,MATCH(3,'产品表 Products'!$W$2:$W$105,0))&"","") -> 放大型压电促动器 | D15: =IFERROR(INDEX('产品表 Products'!$C$2:$C$105,MATCH(3,'产品表 Products'!$W$2:$W$105,0))&"","") -> APA40SM | E15: =IFERROR(INDEX('产品表 Products'!$E$2:$E$105,MATCH(3,'产品表 Products'!$W$2:$W$105,0))&"","") -> 放大型压电促动器 | F15: =IFERROR(INDEX('产品表 Products'!$G$2:$G$105,MATCH(3,'产品表 Products'!$W$2:$W$105,0)),"") -> 54 | G15: =IFERROR(INDEX('产品表 Products'!$H$2:$H$105,MATCH(3,'产品表 Products'!$W$2:$W$105,0))&"","") -> µm | H15: =IFERROR(INDEX('产品表 Products'!$J$2:$J$105,MATCH(3,'产品表 Products'!$W$2:$W$105,0)),"") -> 260 | I15: =IFERROR(INDEX('产品表 Products'!$M$2:$M$105,MATCH(3,'产品表 Products'!$W$2:$W$105,0)),"") -> 4130 | J15: =IFERROR(HYPERLINK(INDEX('产品表 Products'!$X$2:$X$105,MATCH(3,'产品表 Products'!$W$2:$W$105,0)),"打开"),"") -> 打开 | L15: 压电控制器机箱（含电源）
B16: 4 | C16: =IFERROR(INDEX('产品表 Products'!$B$2:$B$105,MATCH(4,'产品表 Products'!$W$2:$W$105,0))&"","") -> 放大型压电促动器 | D16: =IFERROR(INDEX('产品表 Products'!$C$2:$C$105,MATCH(4,'产品表 Products'!$W$2:$W$105,0))&"","") -> APA60SL | E16: =IFERROR(INDEX('产品表 Products'!$E$2:$E$105,MATCH(4,'产品表 Products'!$W$2:$W$105,0))&"","") -> 放大型压电促动器 | F16: =IFERROR(INDEX('产品表 Products'!$G$2:$G$105,MATCH(4,'产品表 Products'!$W$2:$W$105,0)),"") -> 57 | G16: =IFERROR(INDEX('产品表 Products'!$H$2:$H$105,MATCH(4,'产品表 Products'!$W$2:$W$105,0))&"","") -> µm | H16: =IFERROR(INDEX('产品表 Products'!$J$2:$J$105,MATCH(4,'产品表 Products'!$W$2:$W$105,0)),"") -> 390 | I16: =IFERROR(INDEX('产品表 Products'!$M$2:$M$105,MATCH(4,'产品表 Products'!$W$2:$W$105,0)),"") -> 3120 | J16: =IFERROR(HYPERLINK(INDEX('产品表 Products'!$X$2:$X$105,MATCH(4,'产品表 Products'!$W$2:$W$105,0)),"打开"),"") -> 打开 | L16: 嵌入式压电驱动板（OEM）
B17: 5 | C17: =IFERROR(INDEX('产品表 Products'!$B$2:$B$105,MATCH(5,'产品表 Products'!$W$2:$W$105,0))&"","") -> 放大型压电促动器 | D17: =IFERROR(INDEX('产品表 Products'!$C$2:$C$105,MATCH(5,'产品表 Products'!$W$2:$W$105,0))&"","") -> APA60ML | E17: =IFERROR(INDEX('产品表 Products'!$E$2:$E$105,MATCH(5,'产品表 Products'!$W$2:$W$105,0))&"","") -> 放大型压电促动器 | F17: =IFERROR(INDEX('产品表 Products'!$G$2:$G$105,MATCH(5,'产品表 Products'!$W$2:$W$105,0)),"") -> 65 | G17: =IFERROR(INDEX('产品表 Products'!$H$2:$H$105,MATCH(5,'产品表 Products'!$W$2:$W$105,0))&"","") -> µm | H17: =IFERROR(INDEX('产品表 Products'!$J$2:$J$105,MATCH(5,'产品表 Products'!$W$2:$W$105,0)),"") -> 3300 | I17: =IFERROR(INDEX('产品表 Products'!$M$2:$M$105,MATCH(5,'产品表 Products'!$W$2:$W$105,0)),"") -> 2555 | J17: =IFERROR(HYPERLINK(INDEX('产品表 Products'!$X$2:$X$105,MATCH(5,'产品表 Products'!$W$2:$W$105,0)),"打开"),"") -> 打开 | L17: 压电线性放大器
B18: 6 | C18: =IFERROR(INDEX('产品表 Products'!$B$2:$B$105,MATCH(6,'产品表 Products'!$W$2:$W$105,0))&"","") -> 放大型压电促动器 | D18: =IFERROR(INDEX('产品表 Products'!$C$2:$C$105,MATCH(6,'产品表 Products'!$W$2:$W$105,0))&"","") -> APA50XS | E18: =IFERROR(INDEX('产品表 Products'!$E$2:$E$105,MATCH(6,'产品表 Products'!$W$2:$W$105,0))&"","") -> 放大型压电促动器 | F18: =IFERROR(INDEX('产品表 Products'!$G$2:$G$105,MATCH(6,'产品表 Products'!$W$2:$W$105,0)),"") -> 66 | G18: =IFERROR(INDEX('产品表 Products'!$H$2:$H$105,MATCH(6,'产品表 Products'!$W$2:$W$105,0))&"","") -> µm | H18: =IFERROR(INDEX('产品表 Products'!$J$2:$J$105,MATCH(6,'产品表 Products'!$W$2:$W$105,0)),"") -> 16 | I18: =IFERROR(INDEX('产品表 Products'!$M$2:$M$105,MATCH(6,'产品表 Products'!$W$2:$W$105,0)),"") -> 2730 | J18: =IFERROR(HYPERLINK(INDEX('产品表 Products'!$X$2:$X$105,MATCH(6,'产品表 Products'!$W$2:$W$105,0)),"打开"),"") -> 打开 | L18: 数字闭环控制器
B19: 7 | C19: =IFERROR(INDEX('产品表 Products'!$B$2:$B$105,MATCH(7,'产品表 Products'!$W$2:$W$105,0))&"","") -> 放大型压电促动器 | D19: =IFERROR(INDEX('产品表 Products'!$C$2:$C$105,MATCH(7,'产品表 Products'!$W$2:$W$105,0))&"","") -> APA60S | E19: =IFERROR(INDEX('产品表 Products'!$E$2:$E$105,MATCH(7,'产品表 Products'!$W$2:$W$105,0))&"","") -> 放大型压电促动器 | F19: =IFERROR(INDEX('产品表 Products'!$G$2:$G$105,MATCH(7,'产品表 Products'!$W$2:$W$105,0)),"") -> 75 | G19: =IFERROR(INDEX('产品表 Products'!$H$2:$H$105,MATCH(7,'产品表 Products'!$W$2:$W$105,0))&"","") -> µm | H19: =IFERROR(INDEX('产品表 Products'!$J$2:$J$105,MATCH(7,'产品表 Products'!$W$2:$W$105,0)),"") -> 130 | I19: =IFERROR(INDEX('产品表 Products'!$M$2:$M$105,MATCH(7,'产品表 Products'!$W$2:$W$105,0)),"") -> 2860 | J19: =IFERROR(HYPERLINK(INDEX('产品表 Products'!$X$2:$X$105,MATCH(7,'产品表 Products'!$W$2:$W$105,0)),"打开"),"") -> 打开 | L19: 电涡流位移传感器
B20: 8 | C20: =IFERROR(INDEX('产品表 Products'!$B$2:$B$105,MATCH(8,'产品表 Products'!$W$2:$W$105,0))&"","") -> 放大型压电促动器 | D20: =IFERROR(INDEX('产品表 Products'!$C$2:$C$105,MATCH(8,'产品表 Products'!$W$2:$W$105,0))&"","") -> APA60SM | E20: =IFERROR(INDEX('产品表 Products'!$E$2:$E$105,MATCH(8,'产品表 Products'!$W$2:$W$105,0))&"","") -> 放大型压电促动器 | F20: =IFERROR(INDEX('产品表 Products'!$G$2:$G$105,MATCH(8,'产品表 Products'!$W$2:$W$105,0)),"") -> 77 | G20: =IFERROR(INDEX('产品表 Products'!$H$2:$H$105,MATCH(8,'产品表 Products'!$W$2:$W$105,0))&"","") -> µm | H20: =IFERROR(INDEX('产品表 Products'!$J$2:$J$105,MATCH(8,'产品表 Products'!$W$2:$W$105,0)),"") -> 140 | I20: =IFERROR(INDEX('产品表 Products'!$M$2:$M$105,MATCH(8,'产品表 Products'!$W$2:$W$105,0)),"") -> 2802 | J20: =IFERROR(HYPERLINK(INDEX('产品表 Products'!$X$2:$X$105,MATCH(8,'产品表 Products'!$W$2:$W$105,0)),"打开"),"") -> 打开 | L20: 应变片位置传感器及调理板
B21: 9 | C21: =IFERROR(INDEX('产品表 Products'!$B$2:$B$105,MATCH(9,'产品表 Products'!$W$2:$W$105,0))&"","") -> 放大型压电促动器 | D21: =IFERROR(INDEX('产品表 Products'!$C$2:$C$105,MATCH(9,'产品表 Products'!$W$2:$W$105,0))&"","") -> APA95ML | E21: =IFERROR(INDEX('产品表 Products'!$E$2:$E$105,MATCH(9,'产品表 Products'!$W$2:$W$105,0))&"","") -> 放大型压电促动器 | F21: =IFERROR(INDEX('产品表 Products'!$G$2:$G$105,MATCH(9,'产品表 Products'!$W$2:$W$105,0)),"") -> 99 | G21: =IFERROR(INDEX('产品表 Products'!$H$2:$H$105,MATCH(9,'产品表 Products'!$W$2:$W$105,0))&"","") -> µm | H21: =IFERROR(INDEX('产品表 Products'!$J$2:$J$105,MATCH(9,'产品表 Products'!$W$2:$W$105,0)),"") -> 2100 | I21: =IFERROR(INDEX('产品表 Products'!$M$2:$M$105,MATCH(9,'产品表 Products'!$W$2:$W$105,0)),"") -> 2090 | J21: =IFERROR(HYPERLINK(INDEX('产品表 Products'!$X$2:$X$105,MATCH(9,'产品表 Products'!$W$2:$W$105,0)),"打开"),"") -> 打开
B22: 10 | C22: =IFERROR(INDEX('产品表 Products'!$B$2:$B$105,MATCH(10,'产品表 Products'!$W$2:$W$105,0))&"","") -> 放大型压电促动器 | D22: =IFERROR(INDEX('产品表 Products'!$C$2:$C$105,MATCH(10,'产品表 Products'!$W$2:$W$105,0))&"","") -> APA100MML | E22: =IFERROR(INDEX('产品表 Products'!$E$2:$E$105,MATCH(10,'产品表 Products'!$W$2:$W$105,0))&"","") -> 放大型压电促动器 | F22: =IFERROR(INDEX('产品表 Products'!$G$2:$G$105,MATCH(10,'产品表 Products'!$W$2:$W$105,0)),"") -> 100 | G22: =IFERROR(INDEX('产品表 Products'!$H$2:$H$105,MATCH(10,'产品表 Products'!$W$2:$W$105,0))&"","") -> µm | H22: =IFERROR(INDEX('产品表 Products'!$J$2:$J$105,MATCH(10,'产品表 Products'!$W$2:$W$105,0)),"") -> 830 | I22: =IFERROR(INDEX('产品表 Products'!$M$2:$M$105,MATCH(10,'产品表 Products'!$W$2:$W$105,0)),"") -> 1730 | J22: =IFERROR(HYPERLINK(INDEX('产品表 Products'!$X$2:$X$105,MATCH(10,'产品表 Products'!$W$2:$W$105,0)),"打开"),"") -> 打开
B23: 11 | C23: =IFERROR(INDEX('产品表 Products'!$B$2:$B$105,MATCH(11,'产品表 Products'!$W$2:$W$105,0))&"","") -> 放大型压电促动器 | D23: =IFERROR(INDEX('产品表 Products'!$C$2:$C$105,MATCH(11,'产品表 Products'!$W$2:$W$105,0))&"","") -> APA120ML | E23: =IFERROR(INDEX('产品表 Products'!$E$2:$E$105,MATCH(11,'产品表 Products'!$W$2:$W$105,0))&"","") -> 放大型压电促动器 | F23: =IFERROR(INDEX('产品表 Products'!$G$2:$G$105,MATCH(11,'产品表 Products'!$W$2:$W$105,0)),"") -> 120 | G23: =IFERROR(INDEX('产品表 Products'!$H$2:$H$105,MATCH(11,'产品表 Products'!$W$2:$W$105,0))&"","") -> µm | H23: =IFERROR(INDEX('产品表 Products'!$J$2:$J$105,MATCH(11,'产品表 Products'!$W$2:$W$105,0)),"") -> 1500 | I23: =IFERROR(INDEX('产品表 Products'!$M$2:$M$105,MATCH(11,'产品表 Products'!$W$2:$W$105,0)),"") -> 1880 | J23: =IFERROR(HYPERLINK(INDEX('产品表 Products'!$X$2:$X$105,MATCH(11,'产品表 Products'!$W$2:$W$105,0)),"打开"),"") -> 打开
B24: 12 | C24: =IFERROR(INDEX('产品表 Products'!$B$2:$B$105,MATCH(12,'产品表 Products'!$W$2:$W$105,0))&"","") -> 放大型压电促动器 | D24: =IFERROR(INDEX('产品表 Products'!$C$2:$C$105,MATCH(12,'产品表 Products'!$W$2:$W$105,0))&"","") -> APA100M | E24: =IFERROR(INDEX('产品表 Products'!$E$2:$E$105,MATCH(12,'产品表 Products'!$W$2:$W$105,0))&"","") -> 放大型压电促动器 | F24: =IFERROR(INDEX('产品表 Products'!$G$2:$G$105,MATCH(12,'产品表 Products'!$W$2:$W$105,0)),"") -> 125 | G24: =IFERROR(INDEX('产品表 Products'!$H$2:$H$105,MATCH(12,'产品表 Products'!$W$2:$W$105,0))&"","") -> µm | H24: =IFERROR(INDEX('产品表 Products'!$J$2:$J$105,MATCH(12,'产品表 Products'!$W$2:$W$105,0)),"") -> 230 | I24: =IFERROR(INDEX('产品表 Products'!$M$2:$M$105,MATCH(12,'产品表 Products'!$W$2:$W$105,0)),"") -> 1910 | J24: =IFERROR(HYPERLINK(INDEX('产品表 Products'!$X$2:$X$105,MATCH(12,'产品表 Products'!$W$2:$W$105,0)),"打开"),"") -> 打开
B25: 13 | C25: =IFERROR(INDEX('产品表 Products'!$B$2:$B$105,MATCH(13,'产品表 Products'!$W$2:$W$105,0))&"","") -> 放大型压电促动器 | D25: =IFERROR(INDEX('产品表 Products'!$C$2:$C$105,MATCH(13,'产品表 Products'!$W$2:$W$105,0))&"","") -> APA150XXS | E25: =IFERROR(INDEX('产品表 Products'!$E$2:$E$105,MATCH(13,'产品表 Products'!$W$2:$W$105,0))&"","") -> 放大型压电促动器 | F25: =IFERROR(INDEX('产品表 Products'!$G$2:$G$105,MATCH(13,'产品表 Products'!$W$2:$W$105,0)),"") -> 132 | G25: =IFERROR(INDEX('产品表 Products'!$H$2:$H$105,MATCH(13,'产品表 Products'!$W$2:$W$105,0))&"","") -> µm | H25: =IFERROR(INDEX('产品表 Products'!$J$2:$J$105,MATCH(13,'产品表 Products'!$W$2:$W$105,0)),"") -> 3.2 | I25: =IFERROR(INDEX('产品表 Products'!$M$2:$M$105,MATCH(13,'产品表 Products'!$W$2:$W$105,0)),"") -> 1100 | J25: =IFERROR(HYPERLINK(INDEX('产品表 Products'!$X$2:$X$105,MATCH(13,'产品表 Products'!$W$2:$W$105,0)),"打开"),"") -> 打开
B26: 14 | C26: =IFERROR(INDEX('产品表 Products'!$B$2:$B$105,MATCH(14,'产品表 Products'!$W$2:$W$105,0))&"","") -> 放大型压电促动器 | D26: =IFERROR(INDEX('产品表 Products'!$C$2:$C$105,MATCH(14,'产品表 Products'!$W$2:$W$105,0))&"","") -> APA120S | E26: =IFERROR(INDEX('产品表 Products'!$E$2:$E$105,MATCH(14,'产品表 Products'!$W$2:$W$105,0))&"","") -> 放大型压电促动器 | F26: =IFERROR(INDEX('产品表 Products'!$G$2:$G$105,MATCH(14,'产品表 Products'!$W$2:$W$105,0)),"") -> 140 | G26: =IFERROR(INDEX('产品表 Products'!$H$2:$H$105,MATCH(14,'产品表 Products'!$W$2:$W$105,0))&"","") -> µm | H26: =IFERROR(INDEX('产品表 Products'!$J$2:$J$105,MATCH(14,'产品表 Products'!$W$2:$W$105,0)),"") -> 46 | I26: =IFERROR(INDEX('产品表 Products'!$M$2:$M$105,MATCH(14,'产品表 Products'!$W$2:$W$105,0)),"") -> 1340 | J26: =IFERROR(HYPERLINK(INDEX('产品表 Products'!$X$2:$X$105,MATCH(14,'产品表 Products'!$W$2:$W$105,0)),"打开"),"") -> 打开
B27: 15 | C27: =IFERROR(INDEX('产品表 Products'!$B$2:$B$105,MATCH(15,'产品表 Products'!$W$2:$W$105,0))&"","") -> 放大型压电促动器 | D27: =IFERROR(INDEX('产品表 Products'!$C$2:$C$105,MATCH(15,'产品表 Products'!$W$2:$W$105,0))&"","") -> APA150M | E27: =IFERROR(INDEX('产品表 Products'!$E$2:$E$105,MATCH(15,'产品表 Products'!$W$2:$W$105,0))&"","") -> 放大型压电促动器 | F27: =IFERROR(INDEX('产品表 Products'!$G$2:$G$105,MATCH(15,'产品表 Products'!$W$2:$W$105,0)),"") -> 185 | G27: =IFERROR(INDEX('产品表 Products'!$H$2:$H$105,MATCH(15,'产品表 Products'!$W$2:$W$105,0))&"","") -> µm | H27: =IFERROR(INDEX('产品表 Products'!$J$2:$J$105,MATCH(15,'产品表 Products'!$W$2:$W$105,0)),"") -> 130 | I27: =IFERROR(INDEX('产品表 Products'!$M$2:$M$105,MATCH(15,'产品表 Products'!$W$2:$W$105,0)),"") -> 1300 | J27: =IFERROR(HYPERLINK(INDEX('产品表 Products'!$X$2:$X$105,MATCH(15,'产品表 Products'!$W$2:$W$105,0)),"打开"),"") -> 打开
B28: 16 | C28: =IFERROR(INDEX('产品表 Products'!$B$2:$B$105,MATCH(16,'产品表 Products'!$W$2:$W$105,0))&"","") -> 放大型压电促动器 | D28: =IFERROR(INDEX('产品表 Products'!$C$2:$C$105,MATCH(16,'产品表 Products'!$W$2:$W$105,0))&"","") -> APA200ML | E28: =IFERROR(INDEX('产品表 Products'!$E$2:$E$105,MATCH(16,'产品表 Products'!$W$2:$W$105,0))&"","") -> 放大型压电促动器 | F28: =IFERROR(INDEX('产品表 Products'!$G$2:$G$105,MATCH(16,'产品表 Products'!$W$2:$W$105,0)),"") -> 220 | G28: =IFERROR(INDEX('产品表 Products'!$H$2:$H$105,MATCH(16,'产品表 Products'!$W$2:$W$105,0))&"","") -> µm | H28: =IFERROR(INDEX('产品表 Products'!$J$2:$J$105,MATCH(16,'产品表 Products'!$W$2:$W$105,0)),"") -> 780 | I28: =IFERROR(INDEX('产品表 Products'!$M$2:$M$105,MATCH(16,'产品表 Products'!$W$2:$W$105,0)),"") -> 1015 | J28: =IFERROR(HYPERLINK(INDEX('产品表 Products'!$X$2:$X$105,MATCH(16,'产品表 Products'!$W$2:$W$105,0)),"打开"),"") -> 打开
B29: 17 | C29: =IFERROR(INDEX('产品表 Products'!$B$2:$B$105,MATCH(17,'产品表 Products'!$W$2:$W$105,0))&"","") -> 放大型压电促动器 | D29: =IFERROR(INDEX('产品表 Products'!$C$2:$C$105,MATCH(17,'产品表 Products'!$W$2:$W$105,0))&"","") -> APA230L | E29: =IFERROR(INDEX('产品表 Products'!$E$2:$E$105,MATCH(17,'产品表 Products'!$W$2:$W$105,0))&"","") -> 放大型压电促动器 | F29: =IFERROR(INDEX('产品表 Products'!$G$2:$G$105,MATCH(17,'产品表 Products'!$W$2:$W$105,0)),"") -> 230 | G29: =IFERROR(INDEX('产品表 Products'!$H$2:$H$105,MATCH(17,'产品表 Products'!$W$2:$W$105,0))&"","") -> µm | H29: =IFERROR(INDEX('产品表 Products'!$J$2:$J$105,MATCH(17,'产品表 Products'!$W$2:$W$105,0)),"") -> 1300 | I29: =IFERROR(INDEX('产品表 Products'!$M$2:$M$105,MATCH(17,'产品表 Products'!$W$2:$W$105,0)),"") -> 857 | J29: =IFERROR(HYPERLINK(INDEX('产品表 Products'!$X$2:$X$105,MATCH(17,'产品表 Products'!$W$2:$W$105,0)),"打开"),"") -> 打开
B30: 18 | C30: =IFERROR(INDEX('产品表 Products'!$B$2:$B$105,MATCH(18,'产品表 Products'!$W$2:$W$105,0))&"","") -> 放大型压电促动器 | D30: =IFERROR(INDEX('产品表 Products'!$C$2:$C$105,MATCH(18,'产品表 Products'!$W$2:$W$105,0))&"","") -> APA200M | E30: =IFERROR(INDEX('产品表 Products'!$E$2:$E$105,MATCH(18,'产品表 Products'!$W$2:$W$105,0))&"","") -> 放大型压电促动器 | F30: =IFERROR(INDEX('产品表 Products'!$G$2:$G$105,MATCH(18,'产品表 Products'!$W$2:$W$105,0)),"") -> 235 | G30: =IFERROR(INDEX('产品表 Products'!$H$2:$H$105,MATCH(18,'产品表 Products'!$W$2:$W$105,0))&"","") -> µm | H30: =IFERROR(INDEX('产品表 Products'!$J$2:$J$105,MATCH(18,'产品表 Products'!$W$2:$W$105,0)),"") -> 87 | I30: =IFERROR(INDEX('产品表 Products'!$M$2:$M$105,MATCH(18,'产品表 Products'!$W$2:$W$105,0)),"") -> 906 | J30: =IFERROR(HYPERLINK(INDEX('产品表 Products'!$X$2:$X$105,MATCH(18,'产品表 Products'!$W$2:$W$105,0)),"打开"),"") -> 打开
B31: 19 | C31: =IFERROR(INDEX('产品表 Products'!$B$2:$B$105,MATCH(19,'产品表 Products'!$W$2:$W$105,0))&"","") -> 放大型压电促动器 | D31: =IFERROR(INDEX('产品表 Products'!$C$2:$C$105,MATCH(19,'产品表 Products'!$W$2:$W$105,0))&"","") -> APA300ML | E31: =IFERROR(INDEX('产品表 Products'!$E$2:$E$105,MATCH(19,'产品表 Products'!$W$2:$W$105,0))&"","") -> 放大型压电促动器 | F31: =IFERROR(INDEX('产品表 Products'!$G$2:$G$105,MATCH(19,'产品表 Products'!$W$2:$W$105,0)),"") -> 300 | G31: =IFERROR(INDEX('产品表 Products'!$H$2:$H$105,MATCH(19,'产品表 Products'!$W$2:$W$105,0))&"","") -> µm | H31: =IFERROR(INDEX('产品表 Products'!$J$2:$J$105,MATCH(19,'产品表 Products'!$W$2:$W$105,0)),"") -> 540 | I31: =IFERROR(INDEX('产品表 Products'!$M$2:$M$105,MATCH(19,'产品表 Products'!$W$2:$W$105,0)),"") -> 758 | J31: =IFERROR(HYPERLINK(INDEX('产品表 Products'!$X$2:$X$105,MATCH(19,'产品表 Products'!$W$2:$W$105,0)),"打开"),"") -> 打开
B32: 20 | C32: =IFERROR(INDEX('产品表 Products'!$B$2:$B$105,MATCH(20,'产品表 Products'!$W$2:$W$105,0))&"","") -> 放大型压电促动器 | D32: =IFERROR(INDEX('产品表 Products'!$C$2:$C$105,MATCH(20,'产品表 Products'!$W$2:$W$105,0))&"","") -> APA400MML | E32: =IFERROR(INDEX('产品表 Products'!$E$2:$E$105,MATCH(20,'产品表 Products'!$W$2:$W$105,0))&"","") -> 放大型压电促动器 | F32: =IFERROR(INDEX('产品表 Products'!$G$2:$G$105,MATCH(20,'产品表 Products'!$W$2:$W$105,0)),"") -> 355 | G32: =IFERROR(INDEX('产品表 Products'!$H$2:$H$105,MATCH(20,'产品表 Products'!$W$2:$W$105,0))&"","") -> µm | H32: =IFERROR(INDEX('产品表 Products'!$J$2:$J$105,MATCH(20,'产品表 Products'!$W$2:$W$105,0)),"") -> 180 | I32: =IFERROR(INDEX('产品表 Products'!$M$2:$M$105,MATCH(20,'产品表 Products'!$W$2:$W$105,0)),"") -> 634 | J32: =IFERROR(HYPERLINK(INDEX('产品表 Products'!$X$2:$X$105,MATCH(20,'产品表 Products'!$W$2:$W$105,0)),"打开"),"") -> 打开
B33: 21 | C33: =IFERROR(INDEX('产品表 Products'!$B$2:$B$105,MATCH(21,'产品表 Products'!$W$2:$W$105,0))&"","") -> 放大型压电促动器 | D33: =IFERROR(INDEX('产品表 Products'!$C$2:$C$105,MATCH(21,'产品表 Products'!$W$2:$W$105,0))&"","") -> APA400M | E33: =IFERROR(INDEX('产品表 Products'!$E$2:$E$105,MATCH(21,'产品表 Products'!$W$2:$W$105,0))&"","") -> 放大型压电促动器 | F33: =IFERROR(INDEX('产品表 Products'!$G$2:$G$105,MATCH(21,'产品表 Products'!$W$2:$W$105,0)),"") -> 455 | G33: =IFERROR(INDEX('产品表 Products'!$H$2:$H$105,MATCH(21,'产品表 Products'!$W$2:$W$105,0))&"","") -> µm | H33: =IFERROR(INDEX('产品表 Products'!$J$2:$J$105,MATCH(21,'产品表 Products'!$W$2:$W$105,0)),"") -> 34 | I33: =IFERROR(INDEX('产品表 Products'!$M$2:$M$105,MATCH(21,'产品表 Products'!$W$2:$W$105,0)),"") -> 423 | J33: =IFERROR(HYPERLINK(INDEX('产品表 Products'!$X$2:$X$105,MATCH(21,'产品表 Products'!$W$2:$W$105,0)),"打开"),"") -> 打开
B34: 22 | C34: =IFERROR(INDEX('产品表 Products'!$B$2:$B$105,MATCH(22,'产品表 Products'!$W$2:$W$105,0))&"","") -> 放大型压电促动器 | D34: =IFERROR(INDEX('产品表 Products'!$C$2:$C$105,MATCH(22,'产品表 Products'!$W$2:$W$105,0))&"","") -> APA500L | E34: =IFERROR(INDEX('产品表 Products'!$E$2:$E$105,MATCH(22,'产品表 Products'!$W$2:$W$105,0))&"","") -> 放大型压电促动器 | F34: =IFERROR(INDEX('产品表 Products'!$G$2:$G$105,MATCH(22,'产品表 Products'!$W$2:$W$105,0)),"") -> 510 | G34: =IFERROR(INDEX('产品表 Products'!$H$2:$H$105,MATCH(22,'产品表 Products'!$W$2:$W$105,0))&"","") -> µm | H34: =IFERROR(INDEX('产品表 Products'!$J$2:$J$105,MATCH(22,'产品表 Products'!$W$2:$W$105,0)),"") -> 580 | I34: =IFERROR(INDEX('产品表 Products'!$M$2:$M$105,MATCH(22,'产品表 Products'!$W$2:$W$105,0)),"") -> 456 | J34: =IFERROR(HYPERLINK(INDEX('产品表 Products'!$X$2:$X$105,MATCH(22,'产品表 Products'!$W$2:$W$105,0)),"打开"),"") -> 打开
B35: 23 | C35: =IFERROR(INDEX('产品表 Products'!$B$2:$B$105,MATCH(23,'产品表 Products'!$W$2:$W$105,0))&"","") -> 放大型压电促动器 | D35: =IFERROR(INDEX('产品表 Products'!$C$2:$C$105,MATCH(23,'产品表 Products'!$W$2:$W$105,0))&"","") -> APA600M | E35: =IFERROR(INDEX('产品表 Products'!$E$2:$E$105,MATCH(23,'产品表 Products'!$W$2:$W$105,0))&"","") -> 放大型压电促动器 | F35: =IFERROR(INDEX('产品表 Products'!$G$2:$G$105,MATCH(23,'产品表 Products'!$W$2:$W$105,0)),"") -> 550 | G35: =IFERROR(INDEX('产品表 Products'!$H$2:$H$105,MATCH(23,'产品表 Products'!$W$2:$W$105,0))&"","") -> µm | H35: =IFERROR(INDEX('产品表 Products'!$J$2:$J$105,MATCH(23,'产品表 Products'!$W$2:$W$105,0)),"") -> 24 | I35: =IFERROR(INDEX('产品表 Products'!$M$2:$M$105,MATCH(23,'产品表 Products'!$W$2:$W$105,0)),"") -> 316 | J35: =IFERROR(HYPERLINK(INDEX('产品表 Products'!$X$2:$X$105,MATCH(23,'产品表 Products'!$W$2:$W$105,0)),"打开"),"") -> 打开
B36: 24 | C36: =IFERROR(INDEX('产品表 Products'!$B$2:$B$105,MATCH(24,'产品表 Products'!$W$2:$W$105,0))&"","") -> 放大型压电促动器 | D36: =IFERROR(INDEX('产品表 Products'!$C$2:$C$105,MATCH(24,'产品表 Products'!$W$2:$W$105,0))&"","") -> APA500XL | E36: =IFERROR(INDEX('产品表 Products'!$E$2:$E$105,MATCH(24,'产品表 Products'!$W$2:$W$105,0))&"","") -> 放大型压电促动器 | F36: =IFERROR(INDEX('产品表 Products'!$G$2:$G$105,MATCH(24,'产品表 Products'!$W$2:$W$105,0)),"") -> 590 | G36: =IFERROR(INDEX('产品表 Products'!$H$2:$H$105,MATCH(24,'产品表 Products'!$W$2:$W$105,0))&"","") -> µm | H36: =IFERROR(INDEX('产品表 Products'!$J$2:$J$105,MATCH(24,'产品表 Products'!$W$2:$W$105,0)),"") -> 1400 | I36: =IFERROR(INDEX('产品表 Products'!$M$2:$M$105,MATCH(24,'产品表 Products'!$W$2:$W$105,0)),"") -> 345 | J36: =IFERROR(HYPERLINK(INDEX('产品表 Products'!$X$2:$X$105,MATCH(24,'产品表 Products'!$W$2:$W$105,0)),"打开"),"") -> 打开
